Workbook
Name _Toc229405416: 'Danh sách chức năng'!#REF!
Name _Toc229405417: 'Danh sách chức năng'!#REF!
Name _Toc229405418: 'Danh sách chức năng'!#REF!
Name _Toc229405419: 'Danh sách chức năng'!#REF!
Name _Toc229405420: 'Danh sách chức năng'!#REF!
Name _Toc229405421: 'Danh sách chức năng'!#REF!
Name _Toc229405422: 'Danh sách chức năng'!#REF!
Name _Toc229405423: 'Danh sách chức năng'!#REF!
Name _Toc229405424: 'Danh sách chức năng'!#REF!
Name _Toc229405425: 'Danh sách chức năng'!#REF!
Name _Toc229405426: 'Danh sách chức năng'!#REF!
Name _Toc229405427: 'Danh sách chức năng'!#REF!
Name _Toc229405428: 'Danh sách chức năng'!#REF!
Name _Toc229405429: 'Danh sách chức năng'!#REF!
Name _Toc229405430: 'Danh sách chức năng'!#REF!
Name _Toc229405431: 'Danh sách chức năng'!#REF!
Name _Toc229405432: 'Danh sách chức năng'!#REF!
Name _Toc229405433: 'Danh sách chức năng'!#REF!
Name _Toc229405434: 'Danh sách chức năng'!#REF!
Name _Toc229405435: 'Danh sách chức năng'!#REF!
Name _Toc229405436: 'Danh sách chức năng'!#REF!
Name _Toc229405437: 'Danh sách chức năng'!#REF!
Name _Toc229405438: 'Danh sách chức năng'!#REF!
Name _Toc229405439: 'Danh sách chức năng'!#REF!
Name _Toc229405440: 'Danh sách chức năng'!#REF!
Name _Toc229405441: 'Danh sách chức năng'!#REF!
Name _Toc229405442: 'Danh sách chức năng'!#REF!
Name _Toc229405443: 'Danh sách chức năng'!#REF!
Name _Toc229405444: 'Danh sách chức năng'!#REF!
Name _Toc229405445: 'Danh sách chức năng'!#REF!
Name _Toc229405446: 'Danh sách chức năng'!#REF!
Name _Toc229405447: 'Danh sách chức năng'!#REF!
Name _Toc229405448: 'Danh sách chức năng'!#REF!
Name _Toc229405449: 'Danh sách chức năng'!#REF!
Name _Toc229405450: 'Danh sách chức năng'!#REF!
Name _Toc229405451: 'Danh sách chức năng'!#REF!
Name _Toc229405452: 'Danh sách chức năng'!#REF!
Name _Toc229405453: 'Danh sách chức năng'!#REF!
Name _Toc229405454: 'Danh sách chức năng'!#REF!
Name _Toc229405455: 'Danh sách chức năng'!#REF!
Name _Toc229405456: 'Danh sách chức năng'!#REF!
Name _Toc229405457: 'Danh sách chức năng'!#REF!
Name _Toc229405458: 'Danh sách chức năng'!#REF!
Name _Toc229405459: 'Danh sách chức năng'!#REF!
Name _Toc229405460: 'Danh sách chức năng'!#REF!
Name _Toc229405461: 'Danh sách chức năng'!#REF!
Name _Toc229405462: 'Danh sách chức năng'!#REF!
Name _Toc229405463: 'Danh sách chức năng'!#REF!
Name _Toc229405464: 'Danh sách chức năng'!#REF!
Name _Toc229405465: 'Danh sách chức năng'!#REF!
Name _Toc229405466: 'Danh sách chức năng'!#REF!
Name _Toc229405467: 'Danh sách chức năng'!#REF!
Name _Toc229405468: 'Danh sách chức năng'!#REF!
Name _Toc229405469: 'Danh sách chức năng'!#REF!
Name _Toc229405470: 'Danh sách chức năng'!#REF!
Name _Toc229405471: 'Danh sách chức năng'!#REF!
Name _Toc229405472: 'Danh sách chức năng'!#REF!
Name _Toc229405473: 'Danh sách chức năng'!#REF!
Name _Toc229405474: 'Danh sách chức năng'!#REF!
Name _Toc229405475: 'Danh sách chức năng'!#REF!

Sheet Settings
B2: Đã tiếp nhận | C2: Cao | D2: Hiệp | E2: Hưng | F2: Hoàn thành
B3: Đang thực hiện | C3: Trung bình | D3: Thuấn | E3: Duyên Anh | F3: Đang thực hiện
B4: Hoàn thành | C4: Thấp | E4: Thương | F4: Chưa thực hiện
B5: Đã log bug | E5: Gấm
B6: Không sửa

Sheet Danh sách chức năng
B1: DANH SÁCH GIAO VIỆC VIẾT TESTCASE
A2: STT | B2: Chức năng | C2: SRS | E2: Testcase | I2: Ghi chú
C3: Người thực hiện | D3: Hoàn thành | E3: Người thực hiện | F3: Thời gian dự kiến (giờ) | G3: =(COUNTIF(G5:G999,"Hoàn thành")/COUNTA(C5:C999))*100 -> 59.259259 | H3: Thời gian thực hiện (giờ)
A4: =IF(C4<>"",COUNTA($C$4:C4),"") | B4: Thông tin chung
A5: =IF(C5<>"",COUNTA($C$4:C5),"") -> 1 | B5: Sản phẩm | C5: Gấm | D5: Hoàn thành | E5: Gấm | G5: Hoàn thành
A6: =IF(C6<>"",COUNTA($C$4:C6),"") -> 2 | B6: Phân loại sản phẩm | C6: Gấm | D6: Hoàn thành | E6: Gấm | F6: 1 | G6: Hoàn thành
A7: =IF(C7<>"",COUNTA($C$4:C7),"") -> 3 | B7: Thuộc tính sản phẩm | C7: Gấm | D7: Hoàn thành | E7: Gấm | F7: 1 | G7: Hoàn thành
A8: =IF(C8<>"",COUNTA($C$4:C8),"") -> 4 | B8: Bán thành phẩm | C8: Gấm | D8: Hoàn thành | E8: Gấm | F8: 1 | G8: Hoàn thành
A9: =IF(C9<>"",COUNTA($C$4:C9),"") -> 5 | B9: Quản lý thiết bị | C9: Gấm | D9: Hoàn thành | E9: Gấm | F9: 1 | G9: Hoàn thành
A10: =IF(C10<>"",COUNTA($C$4:C10),"") -> 6 | B10: Quản lý dụng cụ | C10: Gấm | D10: Hoàn thành | E10: Gấm | F10: 1 | G10: Hoàn thành
A11: =IF(C11<>"",COUNTA($C$4:C11),"") -> 7 | B11: Quản lý đơn vị đo lường | C11: Gấm | D11: Hoàn thành | E11: Gấm | F11: 1 | G11: Hoàn thành
A12: =IF(C12<>"",COUNTA($C$4:C12),"") -> 8 | B12: Lỗi sản phẩm NG | C12: Hưng | D12: Hoàn thành | E12: Gấm | F12: 1 | G12: Hoàn thành
A13: =IF(C13<>"",COUNTA($C$4:C13),"") -> 9 | B13: Nguyên nhân dừng máy | C13: Hưng | D13: Hoàn thành | E13: Gấm | F13: 1 | G13: Hoàn thành
A14: =IF(C14<>"",COUNTA($C$4:C14),"") -> 10 | B14: Công đoạn | C14: Hưng | D14: Hoàn thành | E14: Gấm | F14: 1 | G14: Hoàn thành
A15: =IF(C15<>"",COUNTA($C$4:C15),"") -> 11 | B15: Quy trình mẫu | C15: Hưng | D15: Hoàn thành | E15: Gấm | F15: 1 | G15: Hoàn thành
A16: =IF(C16<>"",COUNTA($C$4:C16),"") -> 12 | B16: Định mức NVL | C16: Hưng | D16: Hoàn thành | E16: Gấm | F16: 1 | G16: Hoàn thành
A17: =IF(C17<>"",COUNTA($C$4:C17),"") -> 13 | B17: Quy trình công nghệ | C17: Hưng | D17: Hoàn thành | E17: Gấm | F17: 1
A18: =IF(C18<>"",COUNTA($C$4:C18),"") -> 14 | B18: Mẫu báo cáo | C18: Hưng | D18: Hoàn thành | E18: Gấm | F18: 1 | G18: Hoàn thành
A19: =IF(C19<>"",COUNTA($C$4:C19),"") -> 15 | B19: Kho | C19: Thương | D19: Hoàn thành | E19: Gấm | F19: 1 | G19: Hoàn thành
A20: =IF(C20<>"",COUNTA($C$4:C20),"") -> 16 | B20: Kệ kho | C20: Thương | D20: Hoàn thành | E20: Gấm | F20: 1 | G20: Chưa thực hiện
A21: =IF(C21<>"",COUNTA($C$4:C21),"") -> 17 | B21: Mã vạch | C21: Thương | D21: Hoàn thành | E21: Gấm | F21: 1 | G21: Hoàn thành
A22: =IF(C22<>"",COUNTA($C$4:C22),"") -> 18 | B22: Nhà cung cấp | C22: Thương | D22: Hoàn thành | E22: Gấm | F22: 1 | G22: Hoàn thành
A23: =IF(C23<>"",COUNTA($C$4:C23),"") -> 19 | B23: Đơn vị sản xuất | C23: Thương | D23: Hoàn thành | E23: Gấm | F23: 1
A24: =IF(C24<>"",COUNTA($C$4:C24),"") -> 20 | B24: Nhân viên | C24: Thương | D24: Hoàn thành | E24: Gấm | F24: 1 | G24: Hoàn thành
A25: =IF(C25<>"",COUNTA($C$4:C25),"") -> 21 | B25: Ca làm việc | C25: Thương | D25: Hoàn thành | E25: Gấm | F25: 1
A26: =IF(C26<>"",COUNTA($C$4:C26),"") -> 22 | B26: Bậc thợ | C26: Thương | D26: Hoàn thành | E26: Gấm | F26: 1 | G26: Hoàn thành
A27: =IF(C27<>"",COUNTA($C$4:C27),"") -> 23 | B27: Lịch làm việc | C27: Thương | D27: Hoàn thành | E27: Gấm | F27: 1 | G27: Hoàn thành
A28: =IF(C28<>"",COUNTA($C$4:C28),"") | B28: Vật tư | G28: Hoàn thành
A29: =IF(C29<>"",COUNTA($C$4:C29),"") | B29: Hạng mục bảo trì
A30: =IF(C30<>"",COUNTA($C$4:C30),"") | B30: Sản xuất
A31: =IF(C31<>"",COUNTA($C$4:C31),"") -> 24 | B31: Lệnh sản xuất | C31: Duyên Anh | D31: Hoàn thành | E31: Duyên Anh | F31: 8 | G31: Hoàn thành
A32: =IF(C32<>"",COUNTA($C$4:C32),"") -> 25 | B32: Hoạt động sản xuất | C32: Duyên Anh | D32: Hoàn thành | E32: Duyên Anh | F32: 1
A33: =IF(C33<>"",COUNTA($C$4:C33),"") -> 26 | B33: Phân công sản xuất | C33: Duyên Anh | D33: Hoàn thành | E33: Duyên Anh | F33: 1
A34: =IF(C34<>"",COUNTA($C$4:C34),"") -> 27 | B34: Phân công nhân viên | C34: Duyên Anh | D34: Hoàn thành | E34: Duyên Anh | F34: 1
A35: =IF(C35<>"",COUNTA($C$4:C35),"") -> 28 | B35: Bảng phân ca tháng | C35: Duyên Anh | D35: Hoàn thành | E35: Duyên Anh | F35: 1
A36: =IF(C36<>"",COUNTA($C$4:C36),"") -> 29 | B36: Bảng chấm công tháng | C36: Duyên Anh | D36: Hoàn thành | E36: Duyên Anh | F36: 1
A37: =IF(C37<>"",COUNTA($C$4:C37),"") -> 30 | B37: Lịch sử hoạt động | C37: Duyên Anh | D37: Hoàn thành | E37: Thương | F37: 1
A38: =IF(C38<>"",COUNTA($C$4:C38),"") -> 31 | B38: Lịch sử dừng máy | C38: Duyên Anh | D38: Hoàn thành | E38: Thương | F38: 1
A39: =IF(C39<>"",COUNTA($C$4:C39),"") -> 32 | B39: Tổng hợp lệnh sản xuất | C39: Duyên Anh | D39: Hoàn thành | E39: Thương | F39: 1
A40: =IF(C40<>"",COUNTA($C$4:C40),"") | B40: Lập lịch tổng hợp ca
...

Sheet Issue
D1: Link: https://mes-demo.intechno.vn | E1: TK Quản trị hệ thống: demo@z195.vn / 123456 TK nguoi dung: / 123456
A3: Mã lỗi | B3: Ngày log | C3: Tên bug | D3: Các bước thực hiện | E3: Kết quả mong muốn | F3: Kết quả thực tế | G3: Hình ảnh/ video | H3: Mức độ ưu tiên | I3: BA/Tester | J3: Dev | K3: Ngày fix bug | L3: Trạng thái | M3: Ghi chú
C4: =SUBTOTAL(3,C5:C999) -> 2 | G4: Link chứa hình ảnh/ video bugs | H4: =SUBTOTAL(3,H5:H999) -> 2 | L4: =SUBTOTAL(3,L5:L999) -> 2
A5: QLP11-01 | B5: 46167 | C5: [Kho].[Phiếu nhập/ xuất kho].Không bấm "Đặt lại" filter được | D5: B1: Truy cập https://mes-bd.intechno.vn/stock/request B2: Chọn Kho: "Kho nguyên vật liệu 618" B3: Chọn trạng thái bất kỳ “Đã lập kế hoạch” B4: Bấm Đặt lại | E5: - Xóa toàn bộ dữ liệu filter đã nhập - Danh sách dữ liệu trở về trạng thái mặc định | F5: - Không xóa toàn bộ dữ liệu filter đã nhập - Vẫn hiển thị danh sách phiếu theo filter đã nhập | G5: QLP11-01 | H5: Trung bình | I5: Thương | J5: Thuấn | K5: 27/05/2026 | L5: Hoàn thành
A6: LSX021 - LSX028 | B6: 46169 | C6: [Sản xuất].[Lệnh sản xuất].Khi thêm mới lệnh sản xuất cho - Số lượng sản xuất bằng 0 khi lưu ra màn danh sách lệnh sản xuất lại hiện 0/1 - Kiểm tra thêm mới Lệnh sản xuất thành công khi Ngày kết thúc nhỏ hơn Ngày bắt đầu vẫn cho lưu lệnh sản xuất thành công | D6: Bước 1: Nhấn nút "+ Thêm mới" Bước 2: Nhập đầy đủ các trường bắt buộc . Nhập Số lượng sản xuất = 0 Bước 3: Chọn tab "Ngày sản xuất" Bước 4: Nhập "Ngày bắt đầu" = "25/05/2026" Bước 5: Nhập "Ngày kết thúc" = "21/05/2026" Bước 6: Nhấn nút "Lưu" | E6: - Hệ thống chỉ cho phép nhập Số lượng sản xuất lớn hơn 0. Khi người dùng nhập giá trị nhỏ hơn hoặc bằng 0, hệ thống hiển thị thông báo lỗi và không cho phép lưu dữ liệu. - Sau khi tạo mới và lưu Lệnh sản xuất thành công, toàn bộ thông tin hiển thị trên giao diện phải trùng khớp hoàn toàn với dữ liệu được lưu trong database. - Hệ thống chỉ cho phép lưu khi Ngày bắt đầu nhỏ hơn Ngày kết thúc. Nếu Ngày bắt đầu lớn hơn hoặc bằng Ngày kết thúc, hệ thống hiển thị thông báo lỗi và không cho phép lưu dữ liệu. | F6: - Hệ thống vẫn cho phép người dùng nhập Số lượng sản xuất bằng 0. - Khi nhập Số lượng sản xuất = 0 và thực hiện lưu, màn hình danh sách hiển thị giá trị 0/1 trong khi dữ liệu lưu trong database là 0, dẫn đến dữ liệu hiển thị không đồng nhất với database. - Hệ thống vẫn cho phép nhập và lưu Ngày bắt đầu nhỏ hơn Ngày kết thúc đối với cả trường Ngày bắt đầu kế hoạch/Ngày kết thúc kế hoạch và Ngày bắt đầu thực tế/Ngày kết thúc thực tế. | G6: LSX021 - LSX028 | H6: Trung bình | I6: Duyên Anh | J6: Thuấn | K6: 27/05/2027 | L6: Hoàn thành

Sheet Tổng hợp
B1: KẾT QUẢ KIỂM THỬ *
B2: Số trường hợp kiểm thử đạt (P) | C2: =E86 -> #REF! | D2: =C2/$C$6 -> #REF! | F2: Link: https://mes-demo.intechno.vn
B3: Số trường hợp kiểm thử không đạt (F) | C3: =F86 -> #REF! | D3: =C3/$C$6 -> #REF!
B4: Số trường hợp kiểm thử đang xem xét (PE) | C4: =G86 -> #REF! | D4: =C4/$C$6 -> #REF! | F4: TK Quản trị hệ thống: demo@z195.vn / 123456
B5: Số trường hợp kiểm thử chưa thực hiện | C5: =C6-C2-C3-C4 -> #REF! | D5: =C5/$C$6 -> #REF! | F5: TK nguoi dung: / 123456
B6: Tổng số trường hợp kiểm thử | C6: =C86 -> #REF!
A7: BẢNG TRỰC GIAO | X7: HYPERLINK(""&"#'"&'Tổng hợp'!X10&"'!A1"&"";'Tổng hợp'!W10)
A8: STT | B8: BẢNG TRỰC GIAO | C8: Tổng số trường hợp kiểm thử | D8: Tỷ lệ % Cover testing | E8: Đạt (P) | F8: Ko đạt (F) | G8: Đang xem xét (PE) | H8: Chưa thực hiện | I8: Ghi chú | K8: Tên Sheet | X8: Quay lại trang Tổng hợp
B9: Thông tin chung | W9: Thông tin chung
A10: 1 | B10: =HYPERLINK(""&"#'"&'Tổng hợp'!X10&"'!A1"&"",'Tổng hợp'!W10) -> Sản phẩm | C10: =IF(X10<>"",INDIRECT(X10&"!$e$8"),"") -> 159 | D10: =IF(AND(C10<>"",C10<>0),SUM(E10:F10)/C10,"") -> 0 | E10: =IF(X10<>"",INDIRECT(X10&"!$e$4"),"") -> 0 | F10: =IF(X10<>"",INDIRECT(X10&"!$e$5"),"") -> 0 | G10: =IF(X10<>"",INDIRECT("'"&X10&"'!$e$6"),"") -> 0 | H10: =IF(X10<>"",INDIRECT("'"&X10&"'!$e$7"),"") -> 159 | K10: =X10 -> SanPham | W10: Sản phẩm | X10: SanPham
A11: 2 | B11: =HYPERLINK(""&"#'"&'Tổng hợp'!X11&"'!A1"&"",'Tổng hợp'!W11) -> Phân loại sản phẩm | C11: =IF(X11<>"",INDIRECT(X11&"!$e$8"),"") -> 159 | D11: =IF(AND(C11<>"",C11<>0),SUM(E11:F11)/C11,"") -> 0 | E11: =IF(X11<>"",INDIRECT(X11&"!$e$4"),"") -> 0 | F11: =IF(X11<>"",INDIRECT(X11&"!$e$5"),"") -> 0 | G11: =IF(X11<>"",INDIRECT("'"&X11&"'!$e$6"),"") -> 0 | H11: =IF(X11<>"",INDIRECT("'"&X11&"'!$e$7"),"") -> 159 | K11: =X11 -> PhanLoaiSanPham | W11: Phân loại sản phẩm | X11: PhanLoaiSanPham
A12: 3 | B12: =HYPERLINK(""&"#'"&'Tổng hợp'!X12&"'!A1"&"",'Tổng hợp'!W12) -> Thuộc tính sản phẩm | C12: =IF(X12<>"",INDIRECT(X12&"!$e$8"),"") | D12: =IF(AND(C12<>"",C12<>0),SUM(E12:F12)/C12,"") | E12: =IF(X12<>"",INDIRECT(X12&"!$e$4"),"") -> 0 | F12: =IF(X12<>"",INDIRECT(X12&"!$e$5"),"") -> 0 | G12: =IF(X12<>"",INDIRECT("'"&X12&"'!$e$6"),"") -> 0 | H12: =IF(X12<>"",INDIRECT("'"&X12&"'!$e$7"),"") -> 159 | K12: =X12 -> ThuocTinhSanPham | W12: Thuộc tính sản phẩm | X12: ThuocTinhSanPham
A13: 4 | B13: =HYPERLINK(""&"#'"&'Tổng hợp'!X13&"'!A1"&"",'Tổng hợp'!W13) -> Bán thành phẩm | C13: =IF(X13<>"",INDIRECT(X13&"!$e$8"),"") -> #REF! | D13: =IF(AND(C13<>"",C13<>0),SUM(E13:F13)/C13,"") -> #REF! | E13: =IF(X13<>"",INDIRECT(X13&"!$e$4"),"") -> #REF! | F13: =IF(X13<>"",INDIRECT(X13&"!$e$5"),"") -> #REF! | G13: =IF(X13<>"",INDIRECT("'"&X13&"'!$e$6"),"") -> #REF! | H13: =IF(X13<>"",INDIRECT("'"&X13&"'!$e$7"),"") -> #REF! | K13: =X13 -> BanThanhPham | W13: Bán thành phẩm | X13: BanThanhPham
A14: 5 | B14: =HYPERLINK(""&"#'"&'Tổng hợp'!X14&"'!A1"&"",'Tổng hợp'!W14) -> Quản lý thiết bị | C14: =IF(X14<>"",INDIRECT(X14&"!$e$8"),"") -> 159 | D14: =IF(AND(C14<>"",C14<>0),SUM(E14:F14)/C14,"") -> 0 | E14: =IF(X14<>"",INDIRECT(X14&"!$e$4"),"") -> 0 | F14: =IF(X14<>"",INDIRECT(X14&"!$e$5"),"") -> 0 | G14: =IF(X14<>"",INDIRECT("'"&X14&"'!$e$6"),"") -> 0 | H14: =IF(X14<>"",INDIRECT("'"&X14&"'!$e$7"),"") -> 159 | K14: =X14 -> QuanLyThietBi | W14: Quản lý thiết bị | X14: QuanLyThietBi
A15: 8 | B15: =HYPERLINK(""&"#'"&'Tổng hợp'!X15&"'!A1"&"",'Tổng hợp'!W15) -> Quản lý dụng cụ | C15: =IF(X15<>"",INDIRECT(X15&"!$e$8"),"") -> 159 | D15: =IF(AND(C15<>"",C15<>0),SUM(E15:F15)/C15,"") -> 0 | E15: =IF(X15<>"",INDIRECT(X15&"!$e$4"),"") -> 0 | F15: =IF(X15<>"",INDIRECT(X15&"!$e$5"),"") -> 0 | G15: =IF(X15<>"",INDIRECT("'"&X15&"'!$e$6"),"") -> 0 | H15: =IF(X15<>"",INDIRECT("'"&X15&"'!$e$7"),"") -> 159 | K15: =X15 -> QuanLyDungCu | W15: Quản lý dụng cụ | X15: QuanLyDungCu
A16: 9 | B16: =HYPERLINK(""&"#'"&'Tổng hợp'!X16&"'!A1"&"",'Tổng hợp'!W16) -> Quản lý đơn vị đo lường | C16: =IF(X16<>"",INDIRECT(X16&"!$e$8"),"") -> 159 | D16: =IF(AND(C16<>"",C16<>0),SUM(E16:F16)/C16,"") -> 0 | E16: =IF(X16<>"",INDIRECT(X16&"!$e$4"),"") -> 0 | F16: =IF(X16<>"",INDIRECT(X16&"!$e$5"),"") -> 0 | G16: =IF(X16<>"",INDIRECT("'"&X16&"'!$e$6"),"") -> 0 | H16: =IF(X16<>"",INDIRECT("'"&X16&"'!$e$7"),"") -> 159 | K16: =X16 -> QuanLyDonViDoLuong | W16: Quản lý đơn vị đo lường | X16: QuanLyDonViDoLuong
A17: 10 | B17: =HYPERLINK(""&"#'"&'Tổng hợp'!X17&"'!A1"&"",'Tổng hợp'!W17) -> Lỗi sản phẩm NG | C17: =IF(X17<>"",INDIRECT(X17&"!$e$8"),"") -> 159 | D17: =IF(AND(C17<>"",C17<>0),SUM(E17:F17)/C17,"") -> 0 | E17: =IF(X17<>"",INDIRECT(X17&"!$e$4"),"") -> 0 | F17: =IF(X17<>"",INDIRECT(X17&"!$e$5"),"") -> 0 | G17: =IF(X17<>"",INDIRECT("'"&X17&"'!$e$6"),"") -> 0 | H17: =IF(X17<>"",INDIRECT("'"&X17&"'!$e$7"),"") -> 159 | K17: =X17 -> LoiSanPhamNG | W17: Lỗi sản phẩm NG | X17: LoiSanPhamNG
A18: 11 | B18: =HYPERLINK(""&"#'"&'Tổng hợp'!X18&"'!A1"&"",'Tổng hợp'!W18) -> Nguyên nhân dừng máy | C18: =IF(X18<>"",INDIRECT(X18&"!$e$8"),"") -> 159 | D18: =IF(AND(C18<>"",C18<>0),SUM(E18:F18)/C18,"") -> 0 | E18: =IF(X18<>"",INDIRECT(X18&"!$e$4"),"") -> 0 | F18: =IF(X18<>"",INDIRECT(X18&"!$e$5"),"") -> 0 | G18: =IF(X18<>"",INDIRECT("'"&X18&"'!$e$6"),"") -> 0 | H18: =IF(X18<>"",INDIRECT("'"&X18&"'!$e$7"),"") -> 159 | K18: =X18 -> NguyenNhanDungMay | W18: Nguyên nhân dừng máy | X18: NguyenNhanDungMay
A19: 12 | B19: =HYPERLINK(""&"#'"&'Tổng hợp'!X19&"'!A1"&"",'Tổng hợp'!W19) -> Công đoạn | C19: =IF(X19<>"",INDIRECT(X19&"!$e$8"),"") -> 159 | D19: =IF(AND(C19<>"",C19<>0),SUM(E19:F19)/C19,"") -> 0 | E19: =IF(X19<>"",INDIRECT(X19&"!$e$4"),"") -> 0 | F19: =IF(X19<>"",INDIRECT(X19&"!$e$5"),"") -> 0 | G19: =IF(X19<>"",INDIRECT("'"&X19&"'!$e$6"),"") -> 0 | H19: =IF(X19<>"",INDIRECT("'"&X19&"'!$e$7"),"") -> 159 | K19: =X19 -> CongDoan | W19: Công đoạn | X19: CongDoan
A20: 13 | B20: =HYPERLINK(""&"#'"&'Tổng hợp'!X20&"'!A1"&"",'Tổng hợp'!W20) -> Quy trình mẫu | C20: =IF(X20<>"",INDIRECT(X20&"!$e$8"),"") -> #REF! | D20: =IF(AND(C20<>"",C20<>0),SUM(E20:F20)/C20,"") -> #REF! | E20: =IF(X20<>"",INDIRECT(X20&"!$e$4"),"") -> #REF! | F20: =IF(X20<>"",INDIRECT(X20&"!$e$5"),"") -> #REF! | G20: =IF(X20<>"",INDIRECT("'"&X20&"'!$e$6"),"") -> #REF! | H20: =IF(X20<>"",INDIRECT("'"&X20&"'!$e$7"),"") -> #REF! | K20: =X20 -> QuyTrinhMau | W20: Quy trình mẫu | X20: QuyTrinhMau
A21: 14 | B21: =HYPERLINK(""&"#'"&'Tổng hợp'!X21&"'!A1"&"",'Tổng hợp'!W21) -> Định mức NVL | C21: =IF(X21<>"",INDIRECT(X21&"!$e$8"),"") -> #REF! | D21: =IF(AND(C21<>"",C21<>0),SUM(E21:F21)/C21,"") -> #REF! | E21: =IF(X21<>"",INDIRECT(X21&"!$e$4"),"") -> #REF! | F21: =IF(X21<>"",INDIRECT(X21&"!$e$5"),"") -> #REF! | G21: =IF(X21<>"",INDIRECT("'"&X21&"'!$e$6"),"") -> #REF! | H21: =IF(X21<>"",INDIRECT("'"&X21&"'!$e$7"),"") -> #REF! | K21: =X21 -> DinhMucNVL | W21: Định mức NVL | X21: DinhMucNVL
... A34: 16 | B34: =HYPERLINK(""&"#'"&'Tổng hợp'!X34&"'!A1"&"",'Tổng hợp'!W34) -> Hạng mục bảo trì | C34: =IF(X34<>"",INDIRECT(X34&"!$e$8"),"") -> #REF! | D34: =IF(AND(C34<>"",C34<>0),SUM(E34:F34)/C34,"") -> #REF! | E34: =IF(X34<>"",INDIRECT(X34&"!$e$4"),"") -> #REF! | F34: =IF(X34<>"",INDIRECT(X34&"!$e$5"),"") -> #REF! | G34: =IF(X34<>"",INDIRECT("'"&X34&"'!$e$6"),"") -> #REF! | H34: =IF(X34<>"",INDIRECT("'"&X34&"'!$e$7"),"") -> #REF! | K34: =X34 -> HangMucBaoTri | W34: Hạng mục bảo trì | X34: HangMucBaoTri
B35: Sản xuất | C35: =IF(X35<>"",INDIRECT(X35&"!$e$8"),"") | D35: =IF(AND(C35<>"",C35<>0),SUM(E35:F35)/C35,"") | E35: =IF(X35<>"",INDIRECT(X35&"!$e$4"),"") | F35: =IF(X35<>"",INDIRECT(X35&"!$e$5"),"") | G35: =IF(X35<>"",INDIRECT("'"&X35&"'!$e$6"),"") | H35: =IF(X35<>"",INDIRECT("'"&X35&"'!$e$7"),"") | W35: Sản xuất
A36: 50 | B36: =HYPERLINK(""&"#'"&'Tổng hợp'!X36&"'!A1"&"",'Tổng hợp'!W36) -> Lệnh sản xuất | C36: =IF(X36<>"",INDIRECT(X36&"!$e$8"),"") -> 187 | D36: =IF(AND(C36<>"",C36<>0),SUM(E36:F36)/C36,"") -> 0.021390374 | E36: =IF(X36<>"",INDIRECT(X36&"!$e$4"),"") -> 4 | F36: =IF(X36<>"",INDIRECT(X36&"!$e$5"),"") -> 0 | G36: =IF(X36<>"",INDIRECT("'"&X36&"'!$e$6"),"") -> 0 | H36: =IF(X36<>"",INDIRECT("'"&X36&"'!$e$7"),"") -> 183 | K36: =X36 -> LenhSanXuat | W36: Lệnh sản xuất | X36: LenhSanXuat
A37: 51 | B37: =HYPERLINK(""&"#'"&'Tổng hợp'!X37&"'!A1"&"",'Tổng hợp'!W37) -> Hoạt động sản xuất | C37: =IF(X37<>"",INDIRECT(X37&"!$e$8"),"") -> 187 | D37: =IF(AND(C37<>"",C37<>0),SUM(E37:F37)/C37,"") -> 0.021390374 | E37: =IF(X37<>"",INDIRECT(X37&"!$e$4"),"") -> 4 | F37: =IF(X37<>"",INDIRECT(X37&"!$e$5"),"") -> 0 | G37: =IF(X37<>"",INDIRECT("'"&X37&"'!$e$6"),"") -> 0 | H37: =IF(X37<>"",INDIRECT("'"&X37&"'!$e$7"),"") -> 183 | K37: =X37 -> HoatDongSanXuat | W37: Hoạt động sản xuất | X37: HoatDongSanXuat
A38: 52 | B38: =HYPERLINK(""&"#'"&'Tổng hợp'!X38&"'!A1"&"",'Tổng hợp'!W38) -> Phân công sản xuất | C38: =IF(X38<>"",INDIRECT(X38&"!$e$8"),"") -> #REF! | D38: =IF(AND(C38<>"",C38<>0),SUM(E38:F38)/C38,"") -> #REF! | E38: =IF(X38<>"",INDIRECT(X38&"!$e$4"),"") -> #REF! | F38: =IF(X38<>"",INDIRECT(X38&"!$e$5"),"") -> #REF! | G38: =IF(X38<>"",INDIRECT("'"&X38&"'!$e$6"),"") -> #REF! | H38: =IF(X38<>"",INDIRECT("'"&X38&"'!$e$7"),"") -> #REF! | K38: =X38 -> PhanCongSanXuat | W38: Phân công sản xuất | X38: PhanCongSanXuat
A39: 53 | B39: =HYPERLINK(""&"#'"&'Tổng hợp'!X39&"'!A1"&"",'Tổng hợp'!W39) -> Phân công nhân viên | C39: =IF(X39<>"",INDIRECT(X39&"!$e$8"),"") -> #REF! | D39: =IF(AND(C39<>"",C39<>0),SUM(E39:F39)/C39,"") -> #REF! | E39: =IF(X39<>"",INDIRECT(X39&"!$e$4"),"") -> #REF! | F39: =IF(X39<>"",INDIRECT(X39&"!$e$5"),"") -> #REF! | G39: =IF(X39<>"",INDIRECT("'"&X39&"'!$e$6"),"") -> #REF! | H39: =IF(X39<>"",INDIRECT("'"&X39&"'!$e$7"),"") -> #REF! | K39: =X39 -> PhanCongNhanVien | W39: Phân công nhân viên | X39: PhanCongNhanVien
A40: 54 | B40: =HYPERLINK(""&"#'"&'Tổng hợp'!X40&"'!A1"&"",'Tổng hợp'!W40) -> Bảng phân ca tháng | C40: =IF(X40<>"",INDIRECT(X40&"!$e$8"),"") -> #REF! | D40: =IF(AND(C40<>"",C40<>0),SUM(E40:F40)/C40,"") -> #REF! | E40: =IF(X40<>"",INDIRECT(X40&"!$e$4"),"") -> #REF! | F40: =IF(X40<>"",INDIRECT(X40&"!$e$5"),"") -> #REF! | G40: =IF(X40<>"",INDIRECT("'"&X40&"'!$e$6"),"") -> #REF! | H40: =IF(X40<>"",INDIRECT("'"&X40&"'!$e$7"),"") -> #REF! | K40: =X40 -> BangPhanCaThang | W40: Bảng phân ca tháng | X40: BangPhanCaThang
A41: 64 | B41: =HYPERLINK(""&"#'"&'Tổng hợp'!X41&"'!A1"&"",'Tổng hợp'!W41) -> Bảng chấm công tháng | C41: =IF(X41<>"",INDIRECT(X41&"!$e$8"),"") -> #REF! | D41: =IF(AND(C41<>"",C41<>0),SUM(E41:F41)/C41,"") -> #REF! | E41: =IF(X41<>"",INDIRECT(X41&"!$e$4"),"") -> #REF! | F41: =IF(X41<>"",INDIRECT(X41&"!$e$5"),"") -> #REF! | G41: =IF(X41<>"",INDIRECT("'"&X41&"'!$e$6"),"") -> #REF! | H41: =IF(X41<>"",INDIRECT("'"&X41&"'!$e$7"),"") -> #REF! | K41: =X41 -> BangChamCongThang | W41: Bảng chấm công tháng | X41: BangChamCongThang
A42: 65 | B42: =HYPERLINK(""&"#'"&'Tổng hợp'!X42&"'!A1"&"",'Tổng hợp'!W42) -> Lịch sử hoạt động | C42: =IF(X42<>"",INDIRECT(X42&"!$e$8"),"") -> #REF! | D42: =IF(AND(C42<>"",C42<>0),SUM(E42:F42)/C42,"") -> #REF! | E42: =IF(X42<>"",INDIRECT(X42&"!$e$4"),"") -> #REF! | F42: =IF(X42<>"",INDIRECT(X42&"!$e$5"),"") -> #REF! | G42: =IF(X42<>"",INDIRECT("'"&X42&"'!$e$6"),"") -> #REF! | H42: =IF(X42<>"",INDIRECT("'"&X42&"'!$e$7"),"") -> #REF! | K42: =X42 -> LichSuHoatDong | W42: Lịch sử hoạt động | X42: LichSuHoatDong
A43: 66 | B43: =HYPERLINK(""&"#'"&'Tổng hợp'!X43&"'!A1"&"",'Tổng hợp'!W43) -> Lịch sử dừng máy | C43: =IF(X43<>"",INDIRECT(X43&"!$e$8"),"") -> #REF! | D43: =IF(AND(C43<>"",C43<>0),SUM(E43:F43)/C43,"") -> #REF! | E43: =IF(X43<>"",INDIRECT(X43&"!$e$4"),"") -> #REF! | F43: =IF(X43<>"",INDIRECT(X43&"!$e$5"),"") -> #REF! | G43: =IF(X43<>"",INDIRECT("'"&X43&"'!$e$6"),"") -> #REF! | H43: =IF(X43<>"",INDIRECT("'"&X43&"'!$e$7"),"") -> #REF! | K43: =X43 -> LichSuDungMay | W43: Lịch sử dừng máy | X43: LichSuDungMay
A44: 67 | B44: =HYPERLINK(""&"#'"&'Tổng hợp'!X44&"'!A1"&"",'Tổng hợp'!W44) -> Tổng hợp lệnh sản xuất | C44: =IF(X44<>"",INDIRECT(X44&"!$e$8"),"") -> #REF! | D44: =IF(AND(C44<>"",C44<>0),SUM(E44:F44)/C44,"") -> #REF! | E44: =IF(X44<>"",INDIRECT(X44&"!$e$4"),"") -> #REF! | F44: =IF(X44<>"",INDIRECT(X44&"!$e$5"),"") -> #REF! | G44: =IF(X44<>"",INDIRECT("'"&X44&"'!$e$6"),"") -> #REF! | H44: =IF(X44<>"",INDIRECT("'"&X44&"'!$e$7"),"") -> #REF! | K44: =X44 -> TongHopLenhSanXuat | W44: Tổng hợp lệnh sản xuất | X44: TongHopLenhSanXuat
A45: 71 | B45: =HYPERLINK(""&"#'"&'Tổng hợp'!X45&"'!A1"&"",'Tổng hợp'!W45) -> Lập lịch tổng hợp ca | C45: =IF(X45<>"",INDIRECT(X45&"!$e$8"),"") -> #REF! | D45: =IF(AND(C45<>"",C45<>0),SUM(E45:F45)/C45,"") -> #REF! | E45: =IF(X45<>"",INDIRECT(X45&"!$e$4"),"") -> #REF! | F45: =IF(X45<>"",INDIRECT(X45&"!$e$5"),"") -> #REF! | G45: =IF(X45<>"",INDIRECT("'"&X45&"'!$e$6"),"") -> #REF! | H45: =IF(X45<>"",INDIRECT("'"&X45&"'!$e$7"),"") -> #REF! | K45: =X45 -> LapLichTongHopCa | W45: Lập lịch tổng hợp ca | X45: LapLichTongHopCa
A46: 72 | B46: =HYPERLINK(""&"#'"&'Tổng hợp'!X46&"'!A1"&"",'Tổng hợp'!W46) -> Tổng hợp ca sản xuất | C46: =IF(X46<>"",INDIRECT(X46&"!$e$8"),"") -> #REF! | D46: =IF(AND(C46<>"",C46<>0),SUM(E46:F46)/C46,"") -> #REF! | E46: =IF(X46<>"",INDIRECT(X46&"!$e$4"),"") -> #REF! | F46: =IF(X46<>"",INDIRECT(X46&"!$e$5"),"") -> #REF! | G46: =IF(X46<>"",INDIRECT("'"&X46&"'!$e$6"),"") -> #REF! | H46: =IF(X46<>"",INDIRECT("'"&X46&"'!$e$7"),"") -> #REF! | K46: =X46 -> TongHopCaSanXuat | W46: Tổng hợp ca sản xuất | X46: TongHopCaSanXuat
B47: Kho | C47: =IF(X47<>"",INDIRECT(X47&"!$e$8"),"") | D47: =IF(AND(C47<>"",C47<>0),SUM(E47:F47)/C47,"") | E47: =IF(X47<>"",INDIRECT(X47&"!$e$4"),"") | F47: =IF(X47<>"",INDIRECT(X47&"!$e$5"),"") | G47: =IF(X47<>"",INDIRECT("'"&X47&"'!$e$6"),"") | H47: =IF(X47<>"",INDIRECT("'"&X47&"'!$e$7"),"") | W47: Kho
B48: =HYPERLINK(""&"#'"&'Tổng hợp'!X48&"'!A1"&"",'Tổng hợp'!W48) -> Yêu cầu điều vận | C48: =IF(X48<>"",INDIRECT(X48&"!$e$8"),"") -> 294 | D48: =IF(AND(C48<>"",C48<>0),SUM(E48:F48)/C48,"") -> 0.0034013605 | E48: =IF(X48<>"",INDIRECT(X48&"!$e$4"),"") -> 1 | F48: =IF(X48<>"",INDIRECT(X48&"!$e$5"),"") -> 0 | G48: =IF(X48<>"",INDIRECT("'"&X48&"'!$e$6"),"") -> 0 | H48: =IF(X48<>"",INDIRECT("'"&X48&"'!$e$7"),"") -> 293 | K48: =X48 -> YeuCauDieuVan | W48: Yêu cầu điều vận | X48: YeuCauDieuVan
A49: 103 | B49: =HYPERLINK(""&"#'"&'Tổng hợp'!X49&"'!A1"&"",'Tổng hợp'!W49) -> Quản lý phiếu | C49: =IF(X49<>"",INDIRECT(X49&"!$e$8"),"") -> 57 | D49: =IF(AND(C49<>"",C49<>0),SUM(E49:F49)/C49,"") -> 0.01754386 | E49: =IF(X49<>"",INDIRECT(X49&"!$e$4"),"") -> 1 | F49: =IF(X49<>"",INDIRECT(X49&"!$e$5"),"") -> 0 | G49: =IF(X49<>"",INDIRECT("'"&X49&"'!$e$6"),"") -> 0 | H49: =IF(X49<>"",INDIRECT("'"&X49&"'!$e$7"),"") -> 56 | K49: =X49 -> QuanLyPhieu | W49: Quản lý phiếu | X49: QuanLyPhieu
A50: 104 | B50: =HYPERLINK(""&"#'"&'Tổng hợp'!X50&"'!A1"&"",'Tổng hợp'!W50) -> Cấu hình kho | C50: =IF(X50<>"",INDIRECT(X50&"!$e$8"),"") -> 31 | D50: =IF(AND(C50<>"",C50<>0),SUM(E50:F50)/C50,"") -> 0.032258065 | E50: =IF(X50<>"",INDIRECT(X50&"!$e$4"),"") -> 1 | F50: =IF(X50<>"",INDIRECT(X50&"!$e$5"),"") -> 0 | G50: =IF(X50<>"",INDIRECT("'"&X50&"'!$e$6"),"") -> 0 | H50: =IF(X50<>"",INDIRECT("'"&X50&"'!$e$7"),"") -> 30 | K50: =X50 -> CauHinhKho | W50: Cấu hình kho | X50: CauHinhKho
A51: 105 | B51: =HYPERLINK(""&"#'"&'Tổng hợp'!X51&"'!A1"&"",'Tổng hợp'!W51) -> Dòng chuyển kho | C51: =IF(X51<>"",INDIRECT(X51&"!$e$8"),"") -> 25 | D51: =IF(AND(C51<>"",C51<>0),SUM(E51:F51)/C51,"") -> 0.04 | E51: =IF(X51<>"",INDIRECT(X51&"!$e$4"),"") -> 1 | F51: =IF(X51<>"",INDIRECT(X51&"!$e$5"),"") -> 0 | G51: =IF(X51<>"",INDIRECT("'"&X51&"'!$e$6"),"") -> 0 | H51: =IF(X51<>"",INDIRECT("'"&X51&"'!$e$7"),"") -> 24 | K51: =X51 -> DongChuyenKho | W51: Dòng chuyển kho | X51: DongChuyenKho
A52: 106 | B52: =HYPERLINK(""&"#'"&'Tổng hợp'!X52&"'!A1"&"",'Tổng hợp'!W52) -> Kiểm kho | C52: =IF(X52<>"",INDIRECT(X52&"!$e$8"),"") -> 141 | D52: =IF(AND(C52<>"",C52<>0),SUM(E52:F52)/C52,"") -> 0.0070921986 | E52: =IF(X52<>"",INDIRECT(X52&"!$e$4"),"") -> 1 | F52: =IF(X52<>"",INDIRECT(X52&"!$e$5"),"") -> 0 | G52: =IF(X52<>"",INDIRECT("'"&X52&"'!$e$6"),"") -> 0 | H52: =IF(X52<>"",INDIRECT("'"&X52&"'!$e$7"),"") -> 140 | K52: =X52 -> KiemKho | W52: Kiểm kho | X52: KiemKho
...

Sheet SanPham
D1: KỊCH BẢN KIỂM THỬ *
D2: Tên màn hình/Tên chức năng | E2: Sản phẩm
D3: Mã trường hợp kiểm thử | E3: SP
D4: Số trường hợp kiểm thử đạt (P) | E4: 0
D5: Số trường hợp kiểm thử không đạt (F) | E5: 0
D6: Số trường hợp kiểm thử đang xem xét (PE) | E6: 0
D7: Số trường hợp kiểm thử chưa thực hiện | E7: 159
D8: Tổng số trường hợp kiểm thử | E8: 159
D9: Quay lại trang Tổng hợp
A10: Mã trường hợp kiểm thử | B10: Mục đích kiểm thử | C10: Dữ liệu kiểm thử | D10: Các bước thực hiện | E10: Kết quả mong muốn | F10: Chrome | I10: <Firefox> | L10: <Edge> | O10: <Tên trình duyệt 4> | R10: Kết quả hiện tại | S10: Mã lỗi | T10: Ghi chú
F11: Lần 1 | G11: Lần 2 | H11: Lần 3 | I11: Lần 1 | J11: Lần 2 | K11: Lần 3 | L11: Lần 1 | M11: Lần 2 | N11: Lần 3 | O11: Lần 1 | P11: Lần 2 | Q11: Lần 3
B12: Chức năng : Sản phẩm
B13: Tiền điều kiện: Bước 1: Đăng nhập vào hệ thống Bước 2: Chọn modul thông tin chung Bước 3: Chọn "Quản lý sản phẩm" Bước 4: Chọn "Sản phẩm"
B14: Màn hình: Danh sách sản phẩm
A15: =IF(E15<>"",$E$3&"00"&COUNTA($E$15:E15),"") -> SP001 | B15: - Kiểm tra title “Sản phẩm” hiển thị đúng theo thiết kế | E15: Hiển thị đúng giao diện và vị trí theo thiết kế
A16: =IF(E16<>"",$E$3&"00"&COUNTA($E$15:E16),"") -> SP002 | B16: - Kiểm tra vị trí các trường filter hiển thị đúng layout | E16: Hiển thị đúng giao diện và vị trí theo thiết kế
A17: =IF(E17<>"",$E$3&"00"&COUNTA($E$15:E17),"") -> SP003 | B17: - Kiểm tra font chữ, kích thước chữ của label, button, table header đúng thiết kế - Kiểm tra màu chữ đúng theo trạng thái | E17: Hiển thị đúng giao diện và vị trí theo thiết kế
A18: =IF(E18<>"",$E$3&"00"&COUNTA($E$15:E18),"") -> SP004 | B18: Kiểm tra format của các Item (Date, Decimal, …) trên màn hình so với các tài liệu thiết kế Figma | E18: Hiển thị đúng giao diện và vị trí theo thiết kế
A19: =IF(E19<>"",$E$3&"00"&COUNTA($E$15:E19),"") -> SP005 | B19: Kiểm tra đúng loại control: - Dropdown: Đơn vị sản xuất, Loại sản phẩm - Textbox: Mã sản phẩm, Tên sản phẩm | E19: Hiển thị đúng giao diện và vị trí theo thiết kế
A20: =IF(E20<>"",$E$3&"00"&COUNTA($E$15:E20),"") -> SP006 | B20: Kiểm tra hiển thị đúng các cột: - Mã sản phẩm - Tên sản phẩm - Trạng thái - Loại sản phẩm - Mô tả sản phẩm - Hành động | E20: Hiển thị đúng giao diện và vị trí theo thiết kế
A21: =IF(E21<>"",$E$3&"00"&COUNTA($E$15:E21),"") | B21: Tìm kiếm theo Đơn vị sản xuất
A22: =IF(E22<>"",$E$3&"00"&COUNTA($E$15:E22),"") -> SP007 | B22: Kiểm tra hiển thị dropdown “Đơn vị sản xuất” trong màn hình Danh sách sản phẩm khi hệ thống tải đầy đủ dữ liệu | D22: 1. Bấm vào thanh tìm kiếm "Đơn vị sản xuất" | E22: Hệ thống hiển thị đầy đủ danh sách đơn vị sản xuất theo dữ liệu cấu hình
A23: =IF(E23<>"",$E$3&"00"&COUNTA($E$15:E23),"") -> SP008 | B23: Kiểm tra chọn một đơn vị sản xuất từ dropdown trong màn hình Danh sách sản phẩm | D23: 1. Bấm vào dropdown “Đơn vị sản xuất” 2. Chọn đơn vị sản xuất | E23: Hệ thống hiển thị đúng các sản phẩm thuộc đơn vị sản xuất đã chọn
A24: =IF(E24<>"",$E$3&"00"&COUNTA($E$15:E24),"") -> SP009 | B24: Kiểm tra chọn nhiều đơn vị sản xuất từ dropdown trong màn hình Danh sách sản phẩm' | D24: 1. Bấm vào dropdown “Đơn vị sản xuất” 2. Chọn nhiều đơn vị sản xuất | E24: Hệ thống không cho phép chọn nhiều đơn vị sản xuất
A25: =IF(E25<>"",$E$3&"0"&COUNTA($E$15:E25),"") -> SP010 | B25: Kiểm tra thay đổi đơn vị sản xuất đã chọn trong màn hình Danh sách sản phẩm | D25: 1. Bấm vào dropdown “Đơn vị sản xuất” 2. Chọn Đơn vị sản xuất 3. Chọn lại Đơn vị sản xuất khác | E25: Hệ thống cập nhật đúng giá trị mới được chọn
A26: =IF(E26<>"",$E$3&"0"&COUNTA($E$15:E26),"") -> SP011 | B26: Kiểm tra xóa đơn vị sản xuất đã chọn trong màn hình Danh sách sản phẩm | D26: 1. Bấm vào dropdown “Đơn vị sản xuất” 2. Chọn đơn vị sản xuất 3. Bấm icon xóa dữ liệu | E26: Hệ thống xóa đúng dữ liệu đã chọn và đưa dropdown về trạng thái mặc định
A27: =IF(E27<>"",$E$3&"0"&COUNTA($E$15:E27),"") -> SP012 | B27: Kiểm tra tìm kiếm đơn vị sản xuất trong dropdown ở màn hình Danh sách sản phẩm | D27: 1. Bấm vào thanh tìm kiếm "Đơn vị sản xuất" 2. Nhập từ khóa tìm kiếm | E27: Hệ thống hiển thị đúng các đơn vị sản xuất phù hợp với từ khóa
A28: =IF(E28<>"",$E$3&"0"&COUNTA($E$15:E28),"") -> SP013 | B28: Kiểm tra đóng dropdown “Đơn vị sản xuất” khi bấm ra ngoài màn hình trong màn hình Danh sách sản phẩm' | D28: 1. Bấm vào dropdown “Đơn vị sản xuất” 2. Bấm ra ngoài vùng dropdown | E28: Hệ thống đóng dropdown đúng theo thiết kế
A29: =IF(E29<>"",$E$3&"0"&COUNTA($E$15:E29),"") | B29: Tìm kiếm theo Loại sản phẩm
A30: =IF(E30<>"",$E$3&"0"&COUNTA($E$15:E30),"") -> SP014 | B30: Kiểm tra hiển thị dropdown “Loại sản phẩm” trong màn hình Danh sách sản phẩm khi hệ thống tải đầy đủ dữ liệu | D30: 1. Bấm vào thanh tìm kiếm "Loại sản phẩm" | E30: Hệ thống hiển thị đầy đủ danh sách đơn vị sản xuất theo dữ liệu cấu hình
A31: =IF(E31<>"",$E$3&"0"&COUNTA($E$15:E31),"") -> SP015 | B31: Kiểm tra chọn một đơn vị sản xuất từ dropdown trong màn hình Danh sách sản phẩm | D31: 1. Bấm vào dropdown “Loại sản phẩm” 2. Chọn đơn Loại sản phẩm | E31: Hệ thống hiển thị đúng các sản phẩm thuộc đơn vị sản xuất đã chọn
A32: =IF(E32<>"",$E$3&"0"&COUNTA($E$15:E32),"") -> SP016 | B32: Kiểm tra chọn nhiều đơn vị sản xuất từ dropdown trong màn hình Danh sách sản phẩm' | D32: 1. Bấm vào dropdown “Loại sản phẩm” 2. Chọn nhiều Loại sản phẩm | E32: Hệ thống không cho phép chọn nhiều đơn vị sản xuất
A33: =IF(E33<>"",$E$3&"0"&COUNTA($E$15:E33),"") -> SP017 | B33: Kiểm tra thay đổi đơn vị sản xuất đã chọn trong màn hình Danh sách sản phẩm | D33: 1. Bấm vào dropdown “Loại sản phẩm” 2. Chọn Loại sản phẩm 3. Chọn lại Loại sản phẩm khác | E33: Hệ thống cập nhật đúng giá trị mới được chọn
A34: =IF(E34<>"",$E$3&"0"&COUNTA($E$15:E34),"") -> SP018 | B34: Kiểm tra xóa đơn vị sản xuất đã chọn trong màn hình Danh sách sản phẩm | D34: 1. Bấm vào dropdown “Loại sản phẩm” 2. Chọn đơn vị sản xuất 3. Bấm icon xóa dữ liệu | E34: Hệ thống xóa đúng dữ liệu đã chọn và đưa dropdown về trạng thái mặc định
A35: =IF(E35<>"",$E$3&"0"&COUNTA($E$15:E35),"") -> SP019 | B35: Kiểm tra tìm kiếm đơn vị sản xuất trong dropdown ở màn hình Danh sách sản phẩm | D35: 1. Bấm vào thanh tìm kiếm "Loại sản phẩm" 2. Nhập từ khóa tìm kiếm | E35: Hệ thống hiển thị đúng các đơn vị sản xuất phù hợp với từ khóa
A36: =IF(E36<>"",$E$3&"0"&COUNTA($E$15:E36),"") -> SP020 | B36: Kiểm tra đóng dropdown “Loại sản phẩm” khi bấm ra ngoài màn hình trong màn hình Danh sách sản phẩm' | D36: 1. Bấm vào dropdown “Loại sản phẩm” 2. Bấm ra ngoài vùng dropdown | E36: Hệ thống đóng dropdown đúng theo thiết kế
A37: =IF(E37<>"",$E$3&"0"&COUNTA($E$15:E37),"") | B37: Tìm kiếm theo Mã sản phẩm
A38: =IF(E38<>"",$E$3&"0"&COUNTA($E$15:E38),"") -> SP021 | B38: Kiểm tra tìm kiếm sản phẩm thành công theo mã sản phẩm đầy đủ | D38: 1.Bấm vào thanh tìm kiếm "Mã sản phẩm" 2. Nhập Mã sản phẩm vào thanh tìm kiếm 3. Nhấn Enter | E38: Hệ thống hiển thị đúng sản phẩm có mã PRODUCT-1726
A39: =IF(E39<>"",$E$3&"0"&COUNTA($E$15:E39),"") -> SP022 | B39: Kiểm tra tìm kiếm thành công theo mã sản phẩm không đầy đủ | D39: 1.Bấm vào thanh tìm kiếm "Mã sản phẩm" 2. Nhập Mã sản phẩm vào thanh tìm kiếm | E39: Hệ thống hiển thị các sản phẩm chứa giá trị tìm kiếm theo rule hệ thống
A40: =IF(E40<>"",$E$3&"0"&COUNTA($E$15:E40),"") -> SP023 | B40: Kiểm tra tìm kiếm thành công khi có khoảng trắng ở đầu và cuối dữ liệu tìm kiếm | D40: 1.Bấm vào thanh tìm kiếm "Mã sản phẩm" 2. Nhập Mã sản phẩm vào thanh tìm kiếm | E40: Hệ thống tự động loại bỏ khoảng trắng dư thừa và hiển thị đúng kết quả tìm kiếm
...

Sheet ThuocTinhSanPham
D1: KỊCH BẢN KIỂM THỬ *
A2: Tìm kiếm dropdown | D2: Tên màn hình/Tên chức năng | E2: Thuộc tính Thuộc tính Thuộc tính sản phẩm
D3: Mã trường hợp kiểm thử | E3: TTSP
D4: Số trường hợp kiểm thử đạt (P) | E4: 0
D5: Số trường hợp kiểm thử không đạt (F) | E5: 0
D6: Số trường hợp kiểm thử đang xem xét (PE) | E6: 0
D7: Số trường hợp kiểm thử chưa thực hiện | E7: 159
D9: Tổng số trường hợp kiểm thử | E9: 159
D10: Quay lại trang Tổng hợp
A11: Mã trường hợp kiểm thử | B11: Mục đích kiểm thử | C11: Dữ liệu kiểm thử | D11: Các bước thực hiện | E11: Kết quả mong muốn | F11: Chrome | I11: <Firefox> | L11: <Edge> | O11: <Tên trình duyệt 4> | R11: Kết quả hiện tại | S11: Mã lỗi | T11: Ghi chú
F12: Lần 1 | G12: Lần 2 | H12: Lần 3 | I12: Lần 1 | J12: Lần 2 | K12: Lần 3 | L12: Lần 1 | M12: Lần 2 | N12: Lần 3 | O12: Lần 1 | P12: Lần 2 | Q12: Lần 3
B13: Chức năng : Thuộc tính Thuộc tính Thuộc tính sản phẩm
B14: Tiền điều kiện: Bước 1: Đăng nhập vào hệ thống Bước 2: Chọn modul thông tin chung Bước 3: Chọn "Quản lý Thuộc tính Thuộc tính Thuộc tính sản phẩm" Bước 4: Chọn "Phân loại Thuộc tính Thuộc tính sản phẩm"
B15: Màn hình: Danh sách Thuộc tính Thuộc tính Thuộc tính sản phẩm
A16: =IF(E16<>"",$E$3&"00"&COUNTA($E$16:E16),"") -> TTSP001 | B16: - Kiểm tra title “Thuộc tính Thuộc tính Thuộc tính sản phẩm” hiển thị đúng theo thiết kế | E16: Hiển thị đúng giao diện và vị trí theo thiết kế
A17: =IF(E17<>"",$E$3&"00"&COUNTA($E$16:E17),"") -> TTSP002 | B17: - Kiểm tra vị trí các trường filter hiển thị đúng layout | E17: Hiển thị đúng giao diện và vị trí theo thiết kế
A18: =IF(E18<>"",$E$3&"00"&COUNTA($E$16:E18),"") -> TTSP003 | B18: - Kiểm tra font chữ, kích thước chữ của label, button, table header đúng thiết kế - Kiểm tra màu chữ đúng theo trạng thái | E18: Hiển thị đúng giao diện và vị trí theo thiết kế
A19: =IF(E19<>"",$E$3&"00"&COUNTA($E$16:E19),"") -> TTSP004 | B19: Kiểm tra format của các Item (Date, Decimal, …) trên màn hình so với các tài liệu thiết kế Figma | E19: Hiển thị đúng giao diện và vị trí theo thiết kế
A20: =IF(E20<>"",$E$3&"00"&COUNTA($E$16:E20),"") -> TTSP005 | B20: Kiểm tra hiển thị đúng các cột: - Tên - Loại - Giá trị | E20: Hiển thị đúng giao diện và vị trí theo thiết kế
A21: =IF(E21<>"",$E$3&"00"&COUNTA($E$16:E21),"") | B21: Thêm mới Thuộc tính Thuộc tính Thuộc tính sản phẩm
A22: =IF(E22<>"",$E$3&"00"&COUNTA($E$16:E22),"") -> TTSP006 | B22: - Kiểm tra font chữ, kích thước chữ của label, button, table header đúng thiết kế - Kiểm tra màu chữ đúng theo trạng thái | D22: 1. Truy cập màn hình "Thêm mới Thuộc tính Thuộc tính Thuộc tính sản phẩm" | E22: Hiển thị đúng giao diện và vị trí theo thiết kế
A23: =IF(E23<>"",$E$3&"00"&COUNTA($E$16:E23),"") -> TTSP007 | B23: Kiểm tra format của các Item trên màn hình so với các tài liệu thiết kế | D23: 1. Truy cập màn hình "Thêm mới Thuộc tính Thuộc tính Thuộc tính sản phẩm" | E23: Hiển thị đúng giao diện và vị trí theo thiết kế
A24: =IF(E24<>"",$E$3&"00"&COUNTA($E$16:E24),"") -> TTSP008 | B24: Các trường hiển thị đúng loại control theo thiết kế: - Textbox: Mã Thuộc tính Thuộc tính Thuộc tính sản phẩm, Tên Thuộc tính Thuộc tính Thuộc tính sản phẩm | D24: 1. Truy cập màn hình "Thêm mới Thuộc tính Thuộc tính Thuộc tính sản phẩm" | E24: Hiển thị đúng giao diện và vị trí theo thiết kế
A25: =IF(E25<>"",$E$3&"00"&COUNTA($E$16:E25),"") -> TTSP009 | B25: Kiểm tra hiển thị dữ liệu tại trường “Tên Thuộc tính Thuộc tính Thuộc tính sản phẩm”trong màn hình Thêm mới Thuộc tính Thuộc tính Thuộc tính sản phẩm khi để trống dữ liệu | D25: 1. Truy cập màn hình Thêm mới Thuộc tính Thuộc tính Thuộc tính sản phẩm 2. Để trống trường “Thuộc tính Thuộc tính Thuộc tính sản phẩm” 3. Bấm vào nút Lưu | E25: Hệ thống hiển thị thông báo bắt buộc nhập trường “Thuộc tính Thuộc tính Thuộc tính sản phẩm” và không cho phép lưu
A26: =IF(E26<>"",$E$3&"00"&COUNTA($E$16:E26),"") -> TTSP0010 | B26: Kiểm tra hiển thị trường “Tên Thuộc tính Thuộc tính Thuộc tính sản phẩm” trong màn hình Thêm mới Thuộc tính Thuộc tính Thuộc tính sản phẩm khi nhập số ký tự nhỏ hơn độ dài tối thiểu | C26: A | D26: 1. Truy cập màn hình Thêm mới Thuộc tính Thuộc tính Thuộc tính sản phẩm 2. Nhập dữ liệu kiểm thử 3. Bấm vào Lưu | E26: Hiển thị thông báo dữ liệu không đạt độ dài tối thiểu
A27: =IF(E27<>"",$E$3&"00"&COUNTA($E$16:E27),"") -> TTSP0011 | B27: Kiểm tra hiển trường “Tên Thuộc tính Thuộc tính Thuộc tính sản phẩm” trong màn hình Thêm mới Thuộc tính Thuộc tính Thuộc tính sản phẩm khi nhập số ký tự vượt quá độ dài tối đa | C27: Chuỗi vượt quá giới hạn cho phép 155 ký tự | D27: 1. Truy cập màn hình Thêm mới Thuộc tính Thuộc tính Thuộc tính sản phẩm 2. Nhập dữ liệu kiểm thử 3. Bấm vào Lưu | E27: Hiển thị thông báo vượt quá số ký tự cho phép và không cho nhập thêm
A28: =IF(E28<>"",$E$3&"00"&COUNTA($E$16:E28),"") -> TTSP0012 | B28: Kiểm tra hiển thị trường “Tên Thuộc tính Thuộc tính Thuộc tính sản phẩm” trong màn hình Thêm mới Thuộc tính Thuộc tính Thuộc tính sản phẩm khi nhập dữ liệu có chứa khoảng trắng ở đầu và cuối | D28: 1. Truy cập màn hình Thêm mới Thuộc tính Thuộc tính Thuộc tính sản phẩm 2. Nhập dữ liệu kiểm thử 3. Bấm vào Lưu | E28: Hệ thống tự động cắt khoảng trắng và lưu dưới định dạng mong muốn
A29: =IF(E29<>"",$E$3&"00"&COUNTA($E$16:E29),"") -> TTSP0013 | B29: Kiểm tra hiển thị trường “Tên Thuộc tính Thuộc tính Thuộc tính sản phẩm” trong màn hình Thêm mới Thuộc tính Thuộc tính Thuộc tính sản phẩm khi nhập dữ liệu trùng với tên Thuộc tính Thuộc tính Thuộc tính sản phẩm đã tồn tại trong hệ thống | D29: 1. Truy cập màn hình Thêm mới Thuộc tính Thuộc tính Thuộc tính sản phẩm 2. Nhập dữ liệu kiểm thử 3. Bấm vào Lưu | E29: Hiển thị thông báo tên Thuộc tính Thuộc tính Thuộc tính sản phẩm đã tồn tại và không cho lưu
A30: =IF(E30<>"",$E$3&"00"&COUNTA($E$16:E30),"") -> TTSP0014 | B30: Kiểm tra hiển thị trường “Tên Thuộc tính Thuộc tính Thuộc tính sản phẩm” trong màn hình Thêm mới Thuộc tính Thuộc tính Thuộc tính sản phẩm khi nhập dữ liệu hợp lệ và thực hiện lưu thành công | D30: 1. Truy cập màn hình Thêm mới Thuộc tính Thuộc tính Thuộc tính sản phẩm 2. Nhập dữ liệu kiểm thử 3. Bấm vào Lưu | E30: Hệ thống thực hiện lưu dữ liệu thành công. Tạo mới một bản ghi Thuộc tính Thuộc tính Thuộc tính sản phẩm trong cơ sở dữ liệu với thông tin đúng theo dữ liệu đã nhập. Hiển thị bản ghi vừa tạo trong danh sách Thuộc tính Thuộc tính Thuộc tính sản phẩm.
A31: =IF(E31<>"",$E$3&"00"&COUNTA($E$16:E31),"") -> TTSP0015 | B31: Kiểm tra hiển thị trường “Đối tượng” trong màn hình Thêm mới Thuộc tính Thuộc tính sản phẩm khi người dùng thực hiện chọn một Đối tượng | D31: 1. Truy cập màn hình Thêm mới Thuộc tính Thuộc tính sản phẩm 2. Bấm chọn trường “Đối tượng” 3. Chọn một danh mục trong danh sách | E31: Hệ thống hiển thị đúng giá trị danh mục đã chọn tại trường “Đối tượng”
A32: =IF(E32<>"",$E$3&"00"&COUNTA($E$16:E32),"") -> TTSP0016 | B32: Kiểm tra hiển thị trường “Đối tượng” trong màn hình Thêm mới Thuộc tính Thuộc tính sản phẩm khi người dùng chưa chọn Đối tượng | D32: 1. Truy cập màn hình Thêm mới Thuộc tính Thuộc tính sản phẩm 2. Chọn tất cả trường bắt buộc và không chọn trường “Đối tượng” 3. Bấm vào Lưu | E32: Hệ thống không cho phép lưu dữ liệu Hệ thống hiển thị thông báo yêu cầu chọn Đối tượng Trường “Đối tượng” được làm nổi bật viền
A33: =IF(E33<>"",$E$3&"00"&COUNTA($E$16:E33),"") -> TTSP0017 | B33: Kiểm tra hiển thị trường “Đối tượng” trong màn hình Thêm mới Thuộc tính Thuộc tính sản phẩm khi người dùng tìm kiếm Đối tượng trong dropdown | D33: 1. Truy cập màn hình Thêm mới Thuộc tính Thuộc tính sản phẩm 2. Bấm vào trường “Đối tượng” 3. Nhập từ khóa tìm kiếm | E33: Hệ thống hiển thị danh sách thả xuống chỉ hiển thị các danh mục có tên chứa từ khóa Nếu không có kết quả, hiển thị thông báo “Không tìm thấy Đối tượng”. Có thể xóa từ khóa để hiển thị lại toàn bộ danh sách.
A34: =IF(E34<>"",$E$3&"00"&COUNTA($E$16:E34),"") -> TTSP0018 | B34: Kiểm tra hiển thị trường “Đối tượng” trong màn hình Thêm mới Thuộc tính Thuộc tính sản phẩm khi người dùng chọn lại Đối tượng khác | D34: 1. Truy cập màn hình Thêm mới Thuộc tính Thuộc tính sản phẩm 2. Bấm vào trường “Đối tượng” 3. Chọn Danh mục A 4. Chọn Danh mục C | E34: Hệ thống cập nhật đúng giá trị Đối tượng mới được chọn
A35: =IF(E35<>"",$E$3&"00"&COUNTA($E$16:E35),"") -> TTSP0019 | B35: Kiểm tra hiển thị trường “Đối tượng” trong màn hình Thêm mới Thuộc tính Thuộc tính sản phẩm khi thực hiện lưu dữ liệu với Đối tượng hợp lệ | D35: 1. Truy cập màn hình Thêm mới Thuộc tính Thuộc tính sản phẩm 2. Bấm vào trường “Đối tượng” 3. Chọn dữ liệu kiểm thử 4. Bấm vào Lưu | E35: Hệ thống lưu dữ liệu thành công Tạo mới một bản ghi trong cơ sở dữ liệu với Đối tượng đã chọn
A36: =IF(E36<>"",$E$3&"00"&COUNTA($E$16:E36),"") -> TTSP0020 | B36: Kiểm tra hiển thị dropdown trường “Loại” trong màn hình Tạo mới thuộc tính khi người dùng mở màn hình tạo mới. | D36: 1. Truy cập màn hình Thêm mới Thuộc tính Thuộc tính sản phẩm 2. Bấm vào trường “Loại” | E36: Hệ thống hiển thị trường “Loại” dạng dropdown. Khi bấm vào trường, hệ thống hiển thị danh sách loại giá trị để lựa chọn.
A37: =IF(E37<>"",$E$3&"00"&COUNTA($E$16:E37),"") -> TTSP0021 | B37: Kiểm tra chọn giá trị “Giá trị nhập” tại trường “Loại” trong màn hình Tạo mới thuộc tính khi người dùng chọn dữ liệu từ dropdown. | D37: 1. Truy cập màn hình Thêm mới Thuộc tính Thuộc tính sản phẩm 2. Bấm vào trường “Loại” 3. Bấm chọn giá trị "Giá trị nhập" | E37: Hệ thống cho phép chọn giá trị “Giá trị nhập”. Giá trị đã chọn được hiển thị tại trường “Loại”.
A38: =IF(E38<>"",$E$3&"00"&COUNTA($E$16:E38),"") -> TTSP0022 | B38: Kiểm tra chọn giá trị “Danh sách chọn” tại trường “Loại” trong màn hình Tạo mới thuộc tính khi người dùng chọn dữ liệu từ dropdown. | D38: 1. Truy cập màn hình Thêm mới Thuộc tính Thuộc tính sản phẩm 2. Bấm vào trường “Loại” 3. Bấm chọn giá trị "Danh sách chọn" | E38: Hệ thống cho phép chọn giá trị “Danh sách chọn”. Giá trị đã chọn được hiển thị tại trường “Loại”.
A39: =IF(E39<>"",$E$3&"00"&COUNTA($E$16:E39),"") -> TTSP0023 | B39: Kiểm tra hiển thị trường “Giá trị” trong màn hình Tạo mới thuộc tính khi người dùng chọn loại là “Danh sách chọn”. | D39: 1. Truy cập màn hình Thêm mới Thuộc tính Thuộc tính sản phẩm 2. Bấm vào trường “Loại” 3. Bấm chọn giá trị "Danh sách chọn" | E39: Hệ thống hiển thị thêm trường “Giá trị” để người dùng nhập hoặc cấu hình danh sách lựa chọn.
... A54: =IF(E54<>"",$E$3&"00"&COUNTA($E$16:E54),"") -> TTSP0038 | B54: Kiểm tra luồng thêm mới thành công với dữ liệu hợp lệ | D54: 1. Truy cập màn hình “Thêm mới Thuộc tính Thuộc tính sản phẩm” 2. Nhập dữ liệu 3. Bấm vào “Lưu” | E54: Hệ thống hiển thị thông báo lưu thành công, tạo mới bản ghi trong cơ sở dữ liệu và hiển thị dữ liệu vừa tạo trong danh sách Thuộc tính Thuộc tính sản phẩm
A55: =IF(E55<>"",$E$3&"00"&COUNTA($E$16:E55),"") | B55: Sửa Thuộc tính Thuộc tính Thuộc tính sản phẩm
...

Sheet PhanLoaiSanPham
D1: KỊCH BẢN KIỂM THỬ *
D2: Tên màn hình/Tên chức năng | E2: Phân loại sản phẩm
D3: Mã trường hợp kiểm thử | E3: PLSP
D4: Số trường hợp kiểm thử đạt (P) | E4: 0
D5: Số trường hợp kiểm thử không đạt (F) | E5: 0
D6: Số trường hợp kiểm thử đang xem xét (PE) | E6: 0
D7: Số trường hợp kiểm thử chưa thực hiện | E7: 159
D8: Tổng số trường hợp kiểm thử | E8: 159
D9: Quay lại trang Tổng hợp
A10: Mã trường hợp kiểm thử | B10: Mục đích kiểm thử | C10: Dữ liệu kiểm thử | D10: Các bước thực hiện | E10: Kết quả mong muốn | F10: Chrome | I10: <Firefox> | L10: <Edge> | O10: <Tên trình duyệt 4> | R10: Kết quả hiện tại | S10: Mã lỗi | T10: Ghi chú
F11: Lần 1 | G11: Lần 2 | H11: Lần 3 | I11: Lần 1 | J11: Lần 2 | K11: Lần 3 | L11: Lần 1 | M11: Lần 2 | N11: Lần 3 | O11: Lần 1 | P11: Lần 2 | Q11: Lần 3
B12: Chức năng : Danh mục sản phẩm
B13: Tiền điều kiện: Bước 1: Đăng nhập vào hệ thống Bước 2: Chọn modul thông tin chung Bước 3: Chọn "Quản lý Danh mục sản phẩm" Bước 4: Chọn "Phân loại sản phẩm"
B14: Màn hình: Danh sách Danh mục sản phẩm
A15: =BanThanhPhamNoiBo!A16 -> BTPNB001 | B15: - Kiểm tra title “Phân loại sản phẩm” hiển thị đúng theo thiết kế | E15: Hiển thị đúng giao diện và vị trí theo thiết kế
A16: =IF(E16<>"",$E$3&"00"&COUNTA($E$15:E16),"") -> PLSP002 | B16: - Kiểm tra vị trí các trường filter hiển thị đúng layout | E16: Hiển thị đúng giao diện và vị trí theo thiết kế
A17: =IF(E17<>"",$E$3&"00"&COUNTA($E$15:E17),"") -> PLSP003 | B17: - Kiểm tra font chữ, kích thước chữ của label, button, table header đúng thiết kế - Kiểm tra màu chữ đúng theo trạng thái | E17: Hiển thị đúng giao diện và vị trí theo thiết kế
A18: =IF(E18<>"",$E$3&"00"&COUNTA($E$15:E18),"") -> PLSP004 | B18: Kiểm tra format của các Item (Date, Decimal, …) trên màn hình so với các tài liệu thiết kế Figma | E18: Hiển thị đúng giao diện và vị trí theo thiết kế
A19: =IF(E19<>"",$E$3&"00"&COUNTA($E$15:E19),"") -> PLSP005 | B19: Kiểm tra đúng loại control: - Textbox: Mã Danh mục sản phẩm, Tên Danh mục sản phẩm | E19: Hiển thị đúng giao diện và vị trí theo thiết kế
A20: =IF(E20<>"",$E$3&"00"&COUNTA($E$15:E20),"") -> PLSP006 | B20: Kiểm tra hiển thị đúng các cột: - Mã Danh mục sản phẩm - Tên Danh mục sản phẩm - Hành động | E20: Hiển thị đúng giao diện và vị trí theo thiết kế
A21: =IF(E21<>"",$E$3&"00"&COUNTA($E$15:E21),"") | B21: Tìm kiếm theo Mã Danh mục sản phẩm
A22: =IF(E22<>"",$E$3&"00"&COUNTA($E$15:E22),"") -> PLSP007 | B22: Kiểm tra tìm kiếm Danh mục sản phẩm thành công theo mã Danh mục sản phẩm đầy đủ | D22: 1.Bấm vào thanh tìm kiếm "Mã Danh mục sản phẩm" 2. Nhập Mã Danh mục sản phẩm vào thanh tìm kiếm 3. Nhấn Enter | E22: Hệ thống hiển thị đúng Danh mục sản phẩm có mã như đã tìm kiếm
A23: =IF(E23<>"",$E$3&"00"&COUNTA($E$15:E23),"") -> PLSP008 | B23: Kiểm tra tìm kiếm thành công theo mã Danh mục sản phẩm không đầy đủ | D23: 1.Bấm vào thanh tìm kiếm "Mã Danh mục sản phẩm" 2. Nhập Mã Danh mục sản phẩm vào thanh tìm kiếm | E23: Hệ thống hiển thị các Danh mục sản phẩm chứa giá trị tìm kiếm theo rule hệ thống
A24: =IF(E24<>"",$E$3&"00"&COUNTA($E$15:E24),"") -> PLSP009 | B24: Kiểm tra tìm kiếm thành công khi có khoảng trắng ở đầu và cuối dữ liệu tìm kiếm | D24: 1.Bấm vào thanh tìm kiếm "Mã Danh mục sản phẩm" 2. Nhập Mã Danh mục sản phẩm vào thanh tìm kiếm | E24: Hệ thống tự động loại bỏ khoảng trắng dư thừa và hiển thị đúng kết quả tìm kiếm
A25: =IF(E25<>"",$E$3&"0"&COUNTA($E$15:E25),"") -> PLSP010 | B25: Kiểm tra tìm kiếm thành công theo Mã Danh mục sản phẩm khi không tồn tại mã Danh mục sản phẩm | D25: 1.Bấm vào thanh tìm kiếm "Mã Danh mục sản phẩm" 2. Nhập mã Danh mục sản phẩm không tồn tại | E25: Hệ thống hiển thị trạng thái “Không có dữ liệu”
A26: =IF(E26<>"",$E$3&"0"&COUNTA($E$15:E26),"") -> PLSP011 | B26: Kiểm tra xóa thành công dữ liệu tìm kiếm | D26: 1.Bấm vào thanh tìm kiếm "Mã Danh mục sản phẩm" 2. Nhập Mã Danh mục sản phẩm vào thanh tìm kiếm | E26: Hệ thống xóa dữ liệu tìm kiếm và hiển thị lại danh sách mặc định
A27: =IF(E27<>"",$E$3&"0"&COUNTA($E$15:E27),"") | B27: Tìm kiếm theo Tên Danh mục sản phẩm
A28: =IF(E28<>"",$E$3&"0"&COUNTA($E$15:E28),"") -> PLSP012 | B28: Kiểm tra tìm kiếm Danh mục sản phẩm thành công theo Tên Danh mục sản phẩm đầy đủ | D28: 1.Bấm vào thanh tìm kiếm "Tìm kiếm theo Tên Danh mục sản phẩm " 2. Nhập Tên Danh mục sản phẩm vào thanh tìm kiếm | E28: Hệ thống hiển thị đúng Danh mục sản phẩm có mã như đã tìm kiếm
A29: =IF(E29<>"",$E$3&"0"&COUNTA($E$15:E29),"") -> PLSP013 | B29: Kiểm tra tìm kiếm thành công theo Tên Danh mục sản phẩm không đầy đủ | D29: 1.Bấm vào thanh tìm kiếm "Tìm kiếm theo Tên Danh mục sản phẩm " 2. Nhập Tên Danh mục sản phẩm vào thanh tìm kiếm | E29: Hệ thống hiển thị các Danh mục sản phẩm chứa giá trị tìm kiếm theo rule hệ thống
A30: =IF(E30<>"",$E$3&"0"&COUNTA($E$15:E30),"") -> PLSP014 | B30: Kiểm tra tìm kiếm thành công theo Tên Danh mục sản phẩm khi có khoảng trắng ở đầu và cuối dữ liệu tìm kiếm | D30: 1.Bấm vào thanh tìm kiếm "Tìm kiếm theo Tên Danh mục sản phẩm " 2. Nhập Tên Danh mục sản phẩm vào thanh tìm kiếm | E30: Hệ thống tự động loại bỏ khoảng trắng dư thừa và hiển thị đúng kết quả tìm kiếm
A31: =IF(E31<>"",$E$3&"0"&COUNTA($E$15:E31),"") -> PLSP015 | B31: Kiểm tra tìm kiếm thành công theo Mã Danh mục sản phẩm khi không tồn tại mã Danh mục sản phẩm | D31: 1.Bấm vào thanh tìm kiếm "Tìm kiếm theo Tên Danh mục sản phẩm " 2. Nhập Tên Danh mục sản phẩm vào thanh tìm kiếm | E31: Hệ thống hiển thị trạng thái “Không có dữ liệu”
A32: =IF(E32<>"",$E$3&"0"&COUNTA($E$15:E32),"") -> PLSP016 | B32: Kiểm tra xóa thành công dữ liệu tìm kiếm | D32: 1.Bấm vào thanh tìm kiếm "Tìm kiếm theo Tên Danh mục sản phẩm " 2. Nhập Tên Danh mục sản phẩm vào thanh tìm kiếm | E32: Hệ thống xóa dữ liệu tìm kiếm và hiển thị lại danh sách mặc định
A33: =IF(E33<>"",$E$3&"0"&COUNTA($E$15:E33),"") | B33: Xuất file
A34: =IF(E34<>"",$E$3&"0"&COUNTA($E$15:E34),"") -> PLSP017 | B34: Kiểm tra xuất file thành công | D34: 1. Bấm chọn nút xuất file | E34: Hệ thống xuất file thành công và tải file về máy người dùng
A35: =IF(E35<>"",$E$3&"0"&COUNTA($E$15:E35),"") -> PLSP018 | B35: Kiểm tra dữ liệu hiển thị trong file export | D35: 1. Bấm chọn nút xuất file 2. Export file 3. Mở file đã tải | E35: Dữ liệu trong file hiển thị đầy đủ và chính xác theo dữ liệu trên hệ thống
A36: =IF(E36<>"",$E$3&"0"&COUNTA($E$15:E36),"") -> PLSP019 | B36: Kiểm tra export dữ liệu hiển thị đúng theo điều kiện tìm kiếm | D36: 1. Tìm kiếm theo điều kiện tìm kiếm 2. Bấm chọn nút xuất file 3. Export file 4. Mở file đã tải | E36: File export chỉ chứa dữ liệu theo điều kiện đã tìm kiếm
A37: =IF(E37<>"",$E$3&"0"&COUNTA($E$15:E37),"") -> PLSP020 | B37: Kiểm tra export không thành công khi không có dữ liệu | D37: 1. Bấm chọn nút "Xuất file" | E37: Hệ thống hiển thị thông báo "Không có dữ liệu để export" và Hệ thống xuất file không thành công và không tải file về máy người dùng
A38: =IF(E38<>"",$E$3&"0"&COUNTA($E$15:E38),"") | B38: Nhập file
A39: =IF(E39<>"",$E$3&"0"&COUNTA($E$15:E39),"") -> PLSP021 | B39: Kiểm tra hiển thị cửa sổ “Nhập file” | D39: 1. Bấm chọn nút "Nhập file" | E39: Hệ thống hiển thị cửa sổ nhập file đầy đủ các thành phần theo thiết kế
A40: =IF(E40<>"",$E$3&"0"&COUNTA($E$15:E40),"") -> PLSP022 | B40: Kiểm tra chức năng tải mẫu file nhập thành công | D40: 1. Bấm chọn nút "Nhập file" 2. Bấm chọn tải mẫu file "tại đây" | E40: Hệ thống tải xuống đúng file mẫu import
...

Sheet BanThanhPhamNoiBo
D1: KỊCH BẢN KIỂM THỬ *
D2: Tên màn hình/Tên chức năng | E2: Bán thành phẩm nội bộ
D3: Mã trường hợp kiểm thử | E3: BTPNB
D4: Số trường hợp kiểm thử đạt (P) | E4: 0
D5: Số trường hợp kiểm thử không đạt (F) | E5: 0
D6: Số trường hợp kiểm thử đang xem xét (PE) | E6: 0
D7: Số trường hợp kiểm thử chưa thực hiện | E7: 159
D9: Tổng số trường hợp kiểm thử | E9: 159
D10: Quay lại trang Tổng hợp
A11: Mã trường hợp kiểm thử | B11: Mục đích kiểm thử | C11: Dữ liệu kiểm thử | D11: Các bước thực hiện | E11: Kết quả mong muốn | F11: Chrome | I11: <Firefox> | L11: <Edge> | O11: <Tên trình duyệt 4> | R11: Kết quả hiện tại | S11: Mã lỗi | T11: Ghi chú
F12: Lần 1 | G12: Lần 2 | H12: Lần 3 | I12: Lần 1 | J12: Lần 2 | K12: Lần 3 | L12: Lần 1 | M12: Lần 2 | N12: Lần 3 | O12: Lần 1 | P12: Lần 2 | Q12: Lần 3
B13: Chức năng : Bán thành phẩm nội bộ
B14: Tiền điều kiện: Bước 1: Đăng nhập vào hệ thống Bước 2: Chọn modul thông tin chung Bước 3: Chọn "Quản lý sản phẩm" Bước 4: Chọn "Bán thành phẩm nội bộ"
B15: Màn hình: Danh sách Bán thành phẩm nội bộ
A16: =IF(E16<>"",$E$3&"00"&COUNTA($E$16:E16),"") -> BTPNB001 | B16: - Kiểm tra title “Bán thành phẩm nội bộ” hiển thị đúng theo thiết kế | E16: Hiển thị đúng giao diện và vị trí theo thiết kế
A17: =IF(E17<>"",$E$3&"00"&COUNTA($E$16:E17),"") -> BTPNB002 | B17: - Kiểm tra vị trí các trường filter hiển thị đúng layout | E17: Hiển thị đúng giao diện và vị trí theo thiết kế
A18: =IF(E18<>"",$E$3&"00"&COUNTA($E$16:E18),"") -> BTPNB003 | B18: - Kiểm tra font chữ, kích thước chữ của label, button, table header đúng thiết kế - Kiểm tra màu chữ đúng theo trạng thái | E18: Hiển thị đúng giao diện và vị trí theo thiết kế
A19: =IF(E19<>"",$E$3&"00"&COUNTA($E$16:E19),"") -> BTPNB004 | B19: Kiểm tra format của các Item (Date, Decimal, …) trên màn hình so với các tài liệu thiết kế Figma | E19: Hiển thị đúng giao diện và vị trí theo thiết kế
A20: =IF(E20<>"",$E$3&"00"&COUNTA($E$16:E20),"") -> BTPNB005 | B20: Kiểm tra đúng loại control: - Dropdown: Đơn vị sản xuất, Loại Bán thành phẩm nội bộ - Textbox: Mã Bán thành phẩm nội bộ, Tên Bán thành phẩm nội bộ | E20: Hiển thị đúng giao diện và vị trí theo thiết kế
A21: =IF(E21<>"",$E$3&"00"&COUNTA($E$16:E21),"") -> BTPNB006 | B21: Kiểm tra hiển thị đúng các cột: - Mã Bán thành phẩm nội bộ - Tên Bán thành phẩm nội bộ - Trạng thái - Yêu cầu kiểm tra Yêu cầu kiểm tra Yêu cầu kiểm tra PQC - Mô tả Bán thành phẩm nội bộ - Hành động | E21: Hiển thị đúng giao diện và vị trí theo thiết kế
A22: =IF(E22<>"",$E$3&"00"&COUNTA($E$16:E22),"") | B22: Tìm kiếm theo Đơn vị sản xuất
A23: =IF(E23<>"",$E$3&"00"&COUNTA($E$16:E23),"") -> BTPNB007 | B23: Kiểm tra hiển thị dropdown “Đơn vị sản xuất” trong màn hình Danh sách Bán thành phẩm nội bộ khi hệ thống tải đầy đủ dữ liệu | D23: 1. Bấm vào thanh tìm kiếm "Đơn vị sản xuất" | E23: Hệ thống hiển thị đầy đủ danh sách đơn vị sản xuất theo dữ liệu cấu hình
A24: =IF(E24<>"",$E$3&"00"&COUNTA($E$16:E24),"") -> BTPNB008 | B24: Kiểm tra chọn một đơn vị sản xuất từ dropdown trong màn hình Danh sách Bán thành phẩm nội bộ | D24: 1. Bấm vào dropdown “Đơn vị sản xuất” 2. Chọn đơn vị sản xuất | E24: Hệ thống hiển thị đúng các Bán thành phẩm nội bộ thuộc đơn vị sản xuất đã chọn
A25: =IF(E25<>"",$E$3&"00"&COUNTA($E$16:E25),"") -> BTPNB009 | B25: Kiểm tra chọn nhiều đơn vị sản xuất từ dropdown trong màn hình Danh sách Bán thành phẩm nội bộ' | D25: 1. Bấm vào dropdown “Đơn vị sản xuất” 2. Chọn nhiều đơn vị sản xuất | E25: Hệ thống không cho phép chọn nhiều đơn vị sản xuất
A26: =IF(E26<>"",$E$3&"00"&COUNTA($E$16:E26),"") -> BTPNB0010 | B26: Kiểm tra thay đổi đơn vị sản xuất đã chọn trong màn hình Danh sách Bán thành phẩm nội bộ | D26: 1. Bấm vào dropdown “Đơn vị sản xuất” 2. Chọn Đơn vị sản xuất 3. Chọn lại Đơn vị sản xuất khác | E26: Hệ thống cập nhật đúng giá trị mới được chọn
A27: =IF(E27<>"",$E$3&"00"&COUNTA($E$16:E27),"") -> BTPNB0011 | B27: Kiểm tra xóa đơn vị sản xuất đã chọn trong màn hình Danh sách Bán thành phẩm nội bộ | D27: 1. Bấm vào dropdown “Đơn vị sản xuất” 2. Chọn đơn vị sản xuất 3. Bấm icon xóa dữ liệu | E27: Hệ thống xóa đúng dữ liệu đã chọn và đưa dropdown về trạng thái mặc định
A28: =IF(E28<>"",$E$3&"00"&COUNTA($E$16:E28),"") -> BTPNB0012 | B28: Kiểm tra tìm kiếm đơn vị sản xuất trong dropdown ở màn hình Danh sách Bán thành phẩm nội bộ | D28: 1. Bấm vào thanh tìm kiếm "Đơn vị sản xuất" 2. Nhập từ khóa tìm kiếm | E28: Hệ thống hiển thị đúng các đơn vị sản xuất phù hợp với từ khóa
A29: =IF(E29<>"",$E$3&"00"&COUNTA($E$16:E29),"") -> BTPNB0013 | B29: Kiểm tra đóng dropdown “Đơn vị sản xuất” khi bấm ra ngoài màn hình trong màn hình Danh sách Bán thành phẩm nội bộ' | D29: 1. Bấm vào dropdown “Đơn vị sản xuất” 2. Bấm ra ngoài vùng dropdown | E29: Hệ thống đóng dropdown đúng theo thiết kế
A30: =IF(E30<>"",$E$3&"00"&COUNTA($E$16:E30),"") | B30: Tìm kiếm theo Loại Bán thành phẩm nội bộ
A31: =IF(E31<>"",$E$3&"00"&COUNTA($E$16:E31),"") -> BTPNB0014 | B31: Kiểm tra hiển thị dropdown “Loại Bán thành phẩm nội bộ” trong màn hình Danh sách Bán thành phẩm nội bộ khi hệ thống tải đầy đủ dữ liệu | D31: 1. Bấm vào thanh tìm kiếm "Loại Bán thành phẩm nội bộ" | E31: Hệ thống hiển thị đầy đủ danh sách đơn vị sản xuất theo dữ liệu cấu hình
A32: =IF(E32<>"",$E$3&"00"&COUNTA($E$16:E32),"") -> BTPNB0015 | B32: Kiểm tra chọn một đơn vị sản xuất từ dropdown trong màn hình Danh sách Bán thành phẩm nội bộ | D32: 1. Bấm vào dropdown “Loại Bán thành phẩm nội bộ” 2. Chọn đơn vị sản xuất | E32: Hệ thống hiển thị đúng các Bán thành phẩm nội bộ thuộc đơn vị sản xuất đã chọn
A33: =IF(E33<>"",$E$3&"00"&COUNTA($E$16:E33),"") -> BTPNB0016 | B33: Kiểm tra chọn nhiều đơn vị sản xuất từ dropdown trong màn hình Danh sách Bán thành phẩm nội bộ' | D33: 1. Bấm vào dropdown “Loại Bán thành phẩm nội bộ” 2. Chọn nhiều Loại bán thành phẩm nội bộ | E33: Hệ thống không cho phép chọn nhiều đơn vị sản xuất
A34: =IF(E34<>"",$E$3&"00"&COUNTA($E$16:E34),"") -> BTPNB0017 | B34: Kiểm tra thay đổi đơn vị sản xuất đã chọn trong màn hình Danh sách Bán thành phẩm nội bộ | D34: 1. Bấm vào dropdown “Loại Bán thành phẩm nội bộ” 2. Chọn Loại bán thành phẩm nội bộ 3. Chọn lại Loại bán thành phẩm nội bộ khác | E34: Hệ thống cập nhật đúng giá trị mới được chọn
A35: =IF(E35<>"",$E$3&"00"&COUNTA($E$16:E35),"") -> BTPNB0018 | B35: Kiểm tra xóa đơn vị sản xuất đã chọn trong màn hình Danh sách Bán thành phẩm nội bộ | D35: 1. Bấm vào dropdown “Loại Bán thành phẩm nội bộ” 2. Chọn đơn vị sản xuất 3. Bấm icon xóa dữ liệu | E35: Hệ thống xóa đúng dữ liệu đã chọn và đưa dropdown về trạng thái mặc định
A36: =IF(E36<>"",$E$3&"00"&COUNTA($E$16:E36),"") -> BTPNB0019 | B36: Kiểm tra tìm kiếm đơn vị sản xuất trong dropdown ở màn hình Danh sách Bán thành phẩm nội bộ | D36: 1. Bấm vào thanh tìm kiếm "Loại Bán thành phẩm nội bộ" 2. Nhập từ khóa tìm kiếm | E36: Hệ thống hiển thị đúng các đơn vị sản xuất phù hợp với từ khóa
A37: =IF(E37<>"",$E$3&"00"&COUNTA($E$16:E37),"") -> BTPNB0020 | B37: Kiểm tra đóng dropdown “Loại Bán thành phẩm nội bộ” khi bấm ra ngoài màn hình trong màn hình Danh sách Bán thành phẩm nội bộ' | D37: 1. Bấm vào dropdown “Loại Bán thành phẩm nội bộ” 2. Bấm ra ngoài vùng dropdown | E37: Hệ thống đóng dropdown đúng theo thiết kế
A38: =IF(E38<>"",$E$3&"00"&COUNTA($E$16:E38),"") | B38: Tìm kiếm theo Mã Bán thành phẩm nội bộ
A39: =IF(E39<>"",$E$3&"00"&COUNTA($E$16:E39),"") -> BTPNB0021 | B39: Kiểm tra tìm kiếm Bán thành phẩm nội bộ thành công theo mã Bán thành phẩm nội bộ đầy đủ | D39: 1.Bấm vào thanh tìm kiếm "Mã Bán thành phẩm nội bộ" 2. Nhập Mã Bán thành phẩm nội bộ vào thanh tìm kiếm 3. Nhấn Enter | E39: Hệ thống hiển thị đúng Bán thành phẩm nội bộ có mã như đã tìm kiếm
